Workbook

Sheet 总览
A1: AI应用开发工程师 / Python开发实习 学习路线图
A3: 目标岗位 | B3: AI应用开发工程师 / AI Agent开发 / Python开发实习生
A4: 目标城市 | B4: 泉州 / 厦门
A5: 目标公司 | B5: 快商通、美图、众诚则、空陆视觉、小题科技、睿云联、量子堆栈、国投智能等
A6: 开始日期 | B6: 46226
A7: 总任务数 | B7: =COUNTA(任务清单!B4:B200)
A8: 已完成 | B8: =COUNTIF(任务清单!E4:E200,"已完成")
A9: 进行中 | B9: =COUNTIF(任务清单!E4:E200,"进行中")
A10: 完成率 | B10: =IFERROR(B8/B7,0)
A12: 阶段统计
A13: 阶段 | B13: 任务数 | C13: 已完成 | D13: 完成率
A14: 阶段1 | B14: =COUNTIF(任务清单!C4:C200,"阶段1*") | C14: =COUNTIFS(任务清单!C4:C200,"阶段1*",任务清单!E4:E200,"已完成") | D14: =IFERROR(C14/B14,0)
A15: 阶段2 | B15: =COUNTIF(任务清单!C4:C200,"阶段2*") | C15: =COUNTIFS(任务清单!C4:C200,"阶段2*",任务清单!E4:E200,"已完成") | D15: =IFERROR(C15/B15,0)
A16: 阶段3 | B16: =COUNTIF(任务清单!C4:C200,"阶段3*") | C16: =COUNTIFS(任务清单!C4:C200,"阶段3*",任务清单!E4:E200,"已完成") | D16: =IFERROR(C16/B16,0)
A17: 阶段4 | B17: =COUNTIF(任务清单!C4:C200,"阶段4*") | C17: =COUNTIFS(任务清单!C4:C200,"阶段4*",任务清单!E4:E200,"已完成") | D17: =IFERROR(C17/B17,0)
A18: 阶段5 | B18: =COUNTIF(任务清单!C4:C200,"阶段5*") | C18: =COUNTIFS(任务清单!C4:C200,"阶段5*",任务清单!E4:E200,"已完成") | D18: =IFERROR(C18/B18,0)
A19: 阶段6 | B19: =COUNTIF(任务清单!C4:C200,"阶段6*") | C19: =COUNTIFS(任务清单!C4:C200,"阶段6*",任务清单!E4:E200,"已完成") | D19: =IFERROR(C19/B19,0)
A20: 阶段7 | B20: =COUNTIF(任务清单!C4:C200,"阶段7*") | C20: =COUNTIFS(任务清单!C4:C200,"阶段7*",任务清单!E4:E200,"已完成") | D20: =IFERROR(C20/B20,0)
A21: 阶段8 | B21: =COUNTIF(任务清单!C4:C200,"阶段8*") | C21: =COUNTIFS(任务清单!C4:C200,"阶段8*",任务清单!E4:E200,"已完成") | D21: =IFERROR(C21/B21,0)
A22: 阶段9 | B22: =COUNTIF(任务清单!C4:C200,"阶段9*") | C22: =COUNTIFS(任务清单!C4:C200,"阶段9*",任务清单!E4:E200,"已完成") | D22: =IFERROR(C22/B22,0)
A24: （内容由AI生成，仅供参考）

Sheet 任务清单
A3: 序号 | B3: 阶段 | C3: 模块 | D3: 任务名称 | E3: 状态 | F3: 优先级 | G3: 开始日期 | H3: 完成日期 | I3: 学习时长(h) | J3: 产出/链接 | K3: 备注
A4: 1 | B4: 阶段1 | C4: 环境与工具 | D4: Python安装与虚拟环境（venv） | E4: 已完成 | F4: 高 | G4: 46212 | H4: 46212 | I4: 2 | J4: python-learning\.venv
A5: 2 | B5: 阶段1 | C5: 环境与工具 | D5: Git安装与GitHub账号建立 | E5: 已完成 | F5: 高 | G5: 46212 | H5: 46212 | I5: 1
A6: 3 | B6: 阶段1 | C6: 环境与工具 | D6: VS Code + Python插件配置 | E6: 已完成 | F6: 高 | G6: 46212 | H6: 46212 | I6: 1
A7: 4 | B7: 阶段1 | C7: 环境与工具 | D7: .env 文件管理与 API Key 安全 | E7: 已完成 | F7: 高 | G7: 46212 | H7: 46212 | I7: 1 | J7: SILICONFLOW_API_KEY
A8: 5 | B8: 阶段1 | C8: 语法基础 | D8: 变量、数据类型、运算符 | E8: 已完成 | F8: 高 | G8: 46212 | H8: 46214 | I8: 3
A9: 6 | B9: 阶段1 | C9: 语法基础 | D9: 控制流（if/for/while） | E9: 已完成 | F9: 高 | G9: 46212 | H9: 46214 | I9: 3
A10: 7 | B10: 阶段1 | C10: 语法基础 | D10: 函数与模块 | E10: 已完成 | F10: 高 | G10: 46214 | H10: 46216 | I10: 4
A11: 8 | B11: 阶段1 | C11: 语法基础 | D11: 面向对象（类/继承/封装） | E11: 已完成 | F11: 中 | G11: 46214 | H11: 46216 | I11: 4
A12: 9 | B12: 阶段1 | C12: 语法基础 | D12: 异常处理（try/except） | E12: 已完成 | F12: 中 | G12: 46216 | H12: 46218 | I12: 2
A13: 10 | B13: 阶段1 | C13: 数据结构 | D13: 列表、元组、字典、集合 | E13: 已完成 | F13: 高 | G13: 46214 | H13: 46216 | I13: 4
A14: 11 | B14: 阶段1 | C14: 数据结构 | D14: 推导式（list/dict comprehension） | E14: 已完成 | F14: 中 | G14: 46216 | H14: 46218 | I14: 2
A15: 12 | B15: 阶段1 | C15: 数据结构 | D15: 字符串处理（正则表达式） | E15: 已完成 | F15: 中 | G15: 46218 | H15: 46220 | I15: 3
A16: 13 | B16: 阶段1 | C16: 进阶 | D16: 文件 I/O 与 JSON | E16: 未开始 | F16: 中
A17: 14 | B17: 阶段1 | C17: 进阶 | D17: 包管理与 pip/conda | E17: 未开始 | F17: 低
A18: 15 | B18: 阶段1 | C18: 进阶 | D18: 单元测试（pytest） | E18: 未开始 | F18: 中
A19: 16 | B19: 阶段2 | C19: LLM基础 | D19: ChatOpenAI 调用与流式输出 | E19: 已完成 | F19: 高 | G19: 46216 | H19: 46218 | I19: 3 | J19: day6_*.py
A20: 17 | B20: 阶段2 | C20: LLM基础 | D20: PromptTemplate 与 ChatPromptTemplate | E20: 已完成 | F20: 高 | G20: 46216 | H20: 46218 | I20: 3
A21: 18 | B21: 阶段2 | C21: LLM基础 | D21: LCEL 管道符 | 用法 | E21: 已完成 | F21: 高 | G21: 46216 | H21: 46218 | I21: 2
A22: 19 | B22: 阶段2 | C22: LLM基础 | D22: StrOutputParser / JsonOutputParser | E22: 已完成 | F22: 高 | G22: 46216 | H22: 46218 | I22: 2
A23: 20 | B23: 阶段2 | C23: 消息系统 | D23: HumanMessage / AIMessage / SystemMessage | E23: 已完成 | F23: 中 | G23: 46218 | H23: 46220 | I23: 2
A24: 21 | B24: 阶段2 | C24: 消息系统 | D24: MessagesPlaceholder 用法 | E24: 已完成 | F24: 中 | G24: 46218 | H24: 46220 | I24: 2
A25: 22 | B25: 阶段2 | C25: 提示工程 | D25: Few-shot 提示模板 | E25: 未开始 | F25: 中
A26: 23 | B26: 阶段2 | C26: 提示工程 | D26: Prompt 调优实战 | E26: 未开始 | F26: 高
A27: 24 | B27: 阶段2 | C27: 结构化输出 | D27: Pydantic 模型定义 + with_structured_output | E27: 未开始 | F27: 高
A28: 25 | B28: 阶段2 | C28: 回调 | D28: Callback / Token 计数 | E28: 未开始 | F28: 低
A29: 26 | B29: 阶段3 | C29: 文档加载 | D29: TextLoader / DirectoryLoader | E29: 已完成 | F29: 高 | G29: 46218 | H29: 46220 | I29: 2
A30: 27 | B30: 阶段3 | C30: 文档加载 | D30: UnstructuredMarkdownLoader | E30: 已完成 | F30: 中 | G30: 46218 | H30: 46220 | I30: 2 | J30: day9_multi_rag.py | K30: Day9
A31: 28 | B31: 阶段3 | C31: 文档加载 | D31: PDF 加载（PyPDF） | E31: 未开始 | F31: 中
A32: 29 | B32: 阶段3 | C32: 文本切分 | D32: RecursiveCharacterTextSplitter | E32: 已完成 | F32: 高 | G32: 46218 | H32: 46220 | I32: 2
A33: 30 | B33: 阶段3 | C33: 文本切分 | D33: MarkdownHeaderTextSplitter | E33: 未开始 | F33: 中
A34: 31 | B34: 阶段3 | C34: 嵌入模型 | D34: HuggingFaceEmbeddings (BGE) | E34: 已完成 | F34: 高 | G34: 46218 | H34: 46220 | I34: 3 | J34: BAAI/bge-small-zh-v1.5
A35: 32 | B35: 阶段3 | C35: 嵌入模型 | D35: OpenAIEmbeddings（硅基流动） | E35: 已完成 | F35: 中 | G35: 46218 | H35: 46220 | I35: 2
A36: 33 | B36: 阶段3 | C36: 向量数据库 | D36: Chroma 基础（本地持久化） | E36: 已完成 | F36: 高 | G36: 46220 | H36: 46220 | I36: 3 | J36: chroma_multi/
A37: 34 | B37: 阶段3 | C37: 向量数据库 | D37: Retriever 配置（k/MMR/相似度阈值） | E37: 已完成 | F37: 高 | G37: 46220 | H37: 46222 | I37: 2
A38: 35 | B38: 阶段3 | C38: RAG基础 | D38: 单文档 RAG Chain | E38: 已完成 | F38: 高 | G38: 46220 | H38: 46222 | I38: 3
A39: 36 | B39: 阶段3 | C39: RAG基础 | D39: 多文档 RAG Chain | E39: 已完成 | F39: 高 | G39: 46222 | H39: 46222 | I39: 4 | J39: day9_multi_rag.py | K39: Day9
A40: 37 | B40: 阶段3 | C40: RAG进阶 | D40: Reranker 提升召回质量 | E40: 未开始 | F40: 中
A41: 38 | B41: 阶段3 | C41: RAG进阶 | D41: 混合检索（BM25 + 向量） | E41: 未开始 | F41: 中
A42: 39 | B42: 阶段3 | C42: RAG进阶 | D42: 元数据过滤 | E42: 未开始 | F42: 中
...

Sheet 今日打卡
A1: 今日打卡（复制下方任务到对应单元格，完成后打勾 ✓）
A3: 序号 | B3: 任务名称 | C3: 计划日期 | D3: 完成 | E3: 今日心得
A4: 1 | D4: ☐
A5: 2 | D5: ☐
A6: 3 | D6: ☐
A7: 4 | D7: ☐
A8: 5 | D8: ☐
A9: 6 | D9: ☐
A10: 7 | D10: ☐
A11: 8 | D11: ☐
A12: 9 | D12: ☐
A13: 10 | D13: ☐

Sheet 周复盘
A1: 每周复盘（每周末花 10 分钟填写）
A3: 周次 | B3: 本周完成任务 | C3: 总学习时长(h) | D3: 下周计划 | E3: 卡点/问题
A4: 第1周
A5: 第2周
A6: 第3周
A7: 第4周
A8: 第5周
A9: 第6周
A10: 第7周
A11: 第8周
A12: 第9周
A13: 第10周

Sheet 目标公司
A1: 目标公司清单（泉州/厦门）——来自 BOSS直聘、实习僧、智联招聘
A3: 序号 | B3: 公司 | C3: 城市 | D3: 岗位 | E3: 薪资/天 | F3: 来源平台 | G3: JD 关键要求 | H3: 投递进度
A4: 1 | B4: 快商通科技 | C4: 厦门集美 | D4: NLP大模型训练实习（AI Agent） | E4: 200-300 | F4: BOSS直聘 | G4: LLM训练、RLHF、Agent、Python | H4: 未投递
A5: 2 | B5: 快商通科技 | C5: 厦门集美 | D5: NLP算法实习生（可转正） | E5: 200-300 | F5: BOSS直聘 | G5: NLP、文本分类、语义匹配、预训练模型 | H5: 未投递
A6: 3 | B6: 美图公司 | C6: 厦门 | D6: AI应用开发实习生 | E6: 200-250 | F6: 实习僧 | G6: Hadoop/Spark、Python/Java、ML、RAG、LangChain | H6: 未投递
A7: 4 | B7: 众诚则网络科技 | C7: 厦门 | D7: AI Agent应用开发工程师 | E7: 面议 | F7: 厦大嘉庚就业网 | G7: LangChain、Dify、Coze、AutoGen、RAG、FastAPI | H7: 未投递
A8: 5 | B8: 空陆视觉科技(厦门) | C8: 厦门思明 | D8: AI工程师（实习） | E8: 面议 | F8: BOSS直聘 | G8: LangChain、LlamaIndex、Dify、Python | H8: 未投递
A9: 6 | B9: 小题旅行科技 | C9: 厦门 | D9: AI数据实习生 | E9: 180-220 | F9: BOSS直聘 | G9: Python、FastAPI、Coze、LLM、GPT | H9: 未投递
A10: 7 | B10: 睿云联网络通讯 | C10: 厦门思明 | D10: Python开发实习生 | E10: 150-200 | F10: BOSS直聘/智联 | G10: Python、数据结构、HTTP/TCP/IP、多线程 | H10: 未投递
A11: 8 | B11: 量子堆栈科技 | C11: 厦门集美 | D11: Python开发工程师（Django） | E11: 校招 | F11: 国聘/BOSS直聘 | G11: Django 5.2+、GitHub、技术博客 | H11: 未投递
A12: 9 | B12: 国投智能 | C12: 厦门 | D12: Python实习生 | E12: 面议 | F12: BOSS直聘 | G12: Python、数据结构、算法、面向对象 | H12: 未投递
A13: 10 | B13: 厦门知涵拳聚科技 | C13: 厦门集美 | D13: Python开发实习生 | E13: 4-8K·13薪 | F13: BOSS直聘 | G13: Python、RPA、自动化 | H13: 未投递
A14: 11 | B14: 九牧集团 | C14: 泉州南安 | D14: AI实习生 | E14: 100-150 | F14: 智联招聘 | G14: LLM、RAG、LangChain、向量数据库、FastAPI | H14: 未投递

Sheet 求职APP推荐
A1: 求职渠道推荐（按成功率排序）
A3: 排名 | B3: APP/平台 | C3: 适合岗位 | D3: 成功率 | E3: 使用技巧 | F3: 注册链接
A4: 1 | B4: BOSS直聘 | C4: Python开发 / AI应用开发 / 实习 | D4: ★★★★★ | E4: 每天主动聊20个Boss，打招呼要带关键词（RAG/LangChain/Python）。厦门和泉州分开搜。 | F4: https://www.zhipin.com
A5: 2 | B5: 实习僧 | C5: AI应用开发实习 / 暑期实习 | D5: ★★★★★ | E5: 专注实习岗位，美图、众诚则的实习都在这里。简历要突出项目经历。 | F5: https://www.shixiseng.com
A6: 3 | B6: 智联招聘 | C6: Python初级 / AI实习 | D6: ★★★★ | E6: 传统大厂多用智联。搜索'Python 实习 厦门'，按发布时间排序。 | F6: https://www.zhaopin.com
A7: 4 | B7: 牛客网 | C7: AI/算法 笔试题 / 内推 | D7: ★★★★ | E7: 刷算法题+找内推码。搜'厦门 AI实习'找内推帖。 | F7: https://www.nowcoder.com
A8: 5 | B8: 国聘 | C8: 国企/央企 Python岗 | D8: ★★★ | E8: 量子堆栈等国企在此发布。Django项目经验写好。 | F8: https://www.iguopin.com
A9: 6 | B9: 拉勾招聘 | C9: 互联网 Python / AI | D9: ★★★ | E9: 厦门互联网公司较多。直接投递+即时沟通。 | F9: https://www.lagou.com
A10: 7 | B10: 猎聘 | C10: Python后端 / AI工程师 | D10: ★★★ | E10: 偏中高级岗位，但实习也可投。完善简历关键词。 | F10: https://www.liepin.com
A11: 8 | B11: 厦门人才网 | C11: 本地小公司 / 传统IT | D11: ★★★ | E11: 厦门本地中小公司会在这里发。适合保底投递。 | F11: https://www.xmrc.com.cn
A12: 9 | B12: 泉州人才网 | C12: 泉州本地实习 | D12: ★★★ | E12: 泉州本地岗位，九牧等制造企业AI岗会发这里。 | F12: https://www.qzrc.com
A13: 10 | B13: 前程无忧(51job) | C13: 传统行业 Python岗 | D13: ★★ | E13: 金融、制造等传统行业IT岗较多，适合保底。 | F13: https://www.51job.com
B15: 招呼 | C15: 您好，我是应届生，熟练掌握 Python + LangChain + LangGraph，独立完成过基于 RAG 的多文档智能问答系统和多工具 Agent 项目（向量库 Chroma + BGE 嵌入 + FastAPI），对 AI Agent 应用开发有浓厚兴趣，希望能获得实习机会。
